2025-05-13 23:54:35,165 ERROR: Exception on / [GET] [in C:\Users\nilva\AppData\Roaming\Python\Python312\site-packages\flask\app.py:1414]
Traceback (most recent call last):
  File "C:\Users\nilva\AppData\Roaming\Python\Python312\site-packages\flask\app.py", line 2190, in wsgi_app
    response = self.full_dispatch_request()
               ^^^^^^^^^^^^^^^^^^^^^^^^^^^^
  File "C:\Users\nilva\AppData\Roaming\Python\Python312\site-packages\flask\app.py", line 1486, in full_dispatch_request
    rv = self.handle_user_exception(e)
         ^^^^^^^^^^^^^^^^^^^^^^^^^^^^^
  File "C:\Users\nilva\AppData\Roaming\Python\Python312\site-packages\flask\app.py", line 1484, in full_dispatch_request
    rv = self.dispatch_request()
         ^^^^^^^^^^^^^^^^^^^^^^^
  File "C:\Users\nilva\AppData\Roaming\Python\Python312\site-packages\flask\app.py", line 1469, in dispatch_request
    return self.ensure_sync(self.view_functions[rule.endpoint])(**view_args)
           ^^^^^^^^^^^^^^^^^^^^^^^^^^^^^^^^^^^^^^^^^^^^^^^^^^^^^^^^^^^^^^^^^
  File "C:\Users\nilva\estoque_apostilas\app\routes\main.py", line 11, in index
    if current_user.is_authenticated:
       ^^^^^^^^^^^^^^^^^^^^^^^^^^^^^
  File "C:\Users\nilva\AppData\Roaming\Python\Python312\site-packages\werkzeug\local.py", line 311, in __get__
    obj = instance._get_current_object()
          ^^^^^^^^^^^^^^^^^^^^^^^^^^^^^^
  File "C:\Users\nilva\AppData\Roaming\Python\Python312\site-packages\werkzeug\local.py", line 515, in _get_current_object
    return get_name(local())
                    ^^^^^^^
  File "C:\Users\nilva\AppData\Roaming\Python\Python312\site-packages\flask_login\utils.py", line 25, in <lambda>
    current_user = LocalProxy(lambda: _get_user())
                                      ^^^^^^^^^^^
  File "C:\Users\nilva\AppData\Roaming\Python\Python312\site-packages\flask_login\utils.py", line 372, in _get_user
    current_app.login_manager._load_user()
  File "C:\Users\nilva\AppData\Roaming\Python\Python312\site-packages\flask_login\login_manager.py", line 364, in _load_user
    user = self._user_callback(user_id)
           ^^^^^^^^^^^^^^^^^^^^^^^^^^^^
  File "C:\Users\nilva\estoque_apostilas\app\routes\auth.py", line 11, in load_user
    return Usuario.query.get(int(user_id))
           ^^^^^^^^^^^^^
  File "C:\Users\nilva\AppData\Roaming\Python\Python312\site-packages\flask_sqlalchemy\model.py", line 30, in __get__
    return cls.query_class(
           ^^^^^^^^^^^^^^^^
  File "C:\Users\nilva\AppData\Roaming\Python\Python312\site-packages\sqlalchemy\orm\query.py", line 275, in __init__
    self._set_entities(entities)
  File "C:\Users\nilva\AppData\Roaming\Python\Python312\site-packages\sqlalchemy\orm\query.py", line 288, in _set_entities
    coercions.expect(
  File "C:\Users\nilva\AppData\Roaming\Python\Python312\site-packages\sqlalchemy\sql\coercions.py", line 388, in expect
    insp._post_inspect
  File "C:\Users\nilva\AppData\Roaming\Python\Python312\site-packages\sqlalchemy\util\langhelpers.py", line 1257, in __get__
    obj.__dict__[self.__name__] = result = self.fget(obj)
                                           ^^^^^^^^^^^^^^
  File "C:\Users\nilva\AppData\Roaming\Python\Python312\site-packages\sqlalchemy\orm\mapper.py", line 2724, in _post_inspect
    self._check_configure()
  File "C:\Users\nilva\AppData\Roaming\Python\Python312\site-packages\sqlalchemy\orm\mapper.py", line 2401, in _check_configure
    _configure_registries({self.registry}, cascade=True)
  File "C:\Users\nilva\AppData\Roaming\Python\Python312\site-packages\sqlalchemy\orm\mapper.py", line 4213, in _configure_registries
    _do_configure_registries(registries, cascade)
  File "C:\Users\nilva\AppData\Roaming\Python\Python312\site-packages\sqlalchemy\orm\mapper.py", line 4254, in _do_configure_registries
    mapper._post_configure_properties()
  File "C:\Users\nilva\AppData\Roaming\Python\Python312\site-packages\sqlalchemy\orm\mapper.py", line 2418, in _post_configure_properties
    prop.init()
  File "C:\Users\nilva\AppData\Roaming\Python\Python312\site-packages\sqlalchemy\orm\interfaces.py", line 589, in init
    self.do_init()
  File "C:\Users\nilva\AppData\Roaming\Python\Python312\site-packages\sqlalchemy\orm\relationships.py", line 1661, in do_init
    self._generate_backref()
  File "C:\Users\nilva\AppData\Roaming\Python\Python312\site-packages\sqlalchemy\orm\relationships.py", line 2089, in _generate_backref
    raise sa_exc.ArgumentError(
sqlalchemy.exc.ArgumentError: Error creating backref 'movimentacoes' on relationship 'Movimentacao.matricula': property of that name exists on mapper 'Mapper[Matricula(matricula)]'
2025-05-13 23:57:02,688 ERROR: Exception on / [GET] [in C:\Users\nilva\AppData\Roaming\Python\Python312\site-packages\flask\app.py:1414]
Traceback (most recent call last):
  File "C:\Users\nilva\AppData\Roaming\Python\Python312\site-packages\flask\app.py", line 2190, in wsgi_app
    response = self.full_dispatch_request()
               ^^^^^^^^^^^^^^^^^^^^^^^^^^^^
  File "C:\Users\nilva\AppData\Roaming\Python\Python312\site-packages\flask\app.py", line 1486, in full_dispatch_request
    rv = self.handle_user_exception(e)
         ^^^^^^^^^^^^^^^^^^^^^^^^^^^^^
  File "C:\Users\nilva\AppData\Roaming\Python\Python312\site-packages\flask\app.py", line 1484, in full_dispatch_request
    rv = self.dispatch_request()
         ^^^^^^^^^^^^^^^^^^^^^^^
  File "C:\Users\nilva\AppData\Roaming\Python\Python312\site-packages\flask\app.py", line 1469, in dispatch_request
    return self.ensure_sync(self.view_functions[rule.endpoint])(**view_args)
           ^^^^^^^^^^^^^^^^^^^^^^^^^^^^^^^^^^^^^^^^^^^^^^^^^^^^^^^^^^^^^^^^^
  File "C:\Users\nilva\estoque_apostilas\app\routes\main.py", line 11, in index
    if current_user.is_authenticated:
       ^^^^^^^^^^^^^^^^^^^^^^^^^^^^^
  File "C:\Users\nilva\AppData\Roaming\Python\Python312\site-packages\werkzeug\local.py", line 311, in __get__
    obj = instance._get_current_object()
          ^^^^^^^^^^^^^^^^^^^^^^^^^^^^^^
  File "C:\Users\nilva\AppData\Roaming\Python\Python312\site-packages\werkzeug\local.py", line 515, in _get_current_object
    return get_name(local())
                    ^^^^^^^
  File "C:\Users\nilva\AppData\Roaming\Python\Python312\site-packages\flask_login\utils.py", line 25, in <lambda>
    current_user = LocalProxy(lambda: _get_user())
                                      ^^^^^^^^^^^
  File "C:\Users\nilva\AppData\Roaming\Python\Python312\site-packages\flask_login\utils.py", line 372, in _get_user
    current_app.login_manager._load_user()
  File "C:\Users\nilva\AppData\Roaming\Python\Python312\site-packages\flask_login\login_manager.py", line 364, in _load_user
    user = self._user_callback(user_id)
           ^^^^^^^^^^^^^^^^^^^^^^^^^^^^
  File "C:\Users\nilva\estoque_apostilas\app\routes\auth.py", line 11, in load_user
    return Usuario.query.get(int(user_id))
           ^^^^^^^^^^^^^
  File "C:\Users\nilva\AppData\Roaming\Python\Python312\site-packages\flask_sqlalchemy\model.py", line 30, in __get__
    return cls.query_class(
           ^^^^^^^^^^^^^^^^
  File "C:\Users\nilva\AppData\Roaming\Python\Python312\site-packages\sqlalchemy\orm\query.py", line 275, in __init__
    self._set_entities(entities)
  File "C:\Users\nilva\AppData\Roaming\Python\Python312\site-packages\sqlalchemy\orm\query.py", line 288, in _set_entities
    coercions.expect(
  File "C:\Users\nilva\AppData\Roaming\Python\Python312\site-packages\sqlalchemy\sql\coercions.py", line 388, in expect
    insp._post_inspect
  File "C:\Users\nilva\AppData\Roaming\Python\Python312\site-packages\sqlalchemy\util\langhelpers.py", line 1257, in __get__
    obj.__dict__[self.__name__] = result = self.fget(obj)
                                           ^^^^^^^^^^^^^^
  File "C:\Users\nilva\AppData\Roaming\Python\Python312\site-packages\sqlalchemy\orm\mapper.py", line 2724, in _post_inspect
    self._check_configure()
  File "C:\Users\nilva\AppData\Roaming\Python\Python312\site-packages\sqlalchemy\orm\mapper.py", line 2401, in _check_configure
    _configure_registries({self.registry}, cascade=True)
  File "C:\Users\nilva\AppData\Roaming\Python\Python312\site-packages\sqlalchemy\orm\mapper.py", line 4213, in _configure_registries
    _do_configure_registries(registries, cascade)
  File "C:\Users\nilva\AppData\Roaming\Python\Python312\site-packages\sqlalchemy\orm\mapper.py", line 4250, in _do_configure_registries
    raise e
sqlalchemy.exc.InvalidRequestError: One or more mappers failed to initialize - can't proceed with initialization of other mappers. Triggering mapper: 'Mapper[Movimentacao(movimentacao)]'. Original exception was: Error creating backref 'movimentacoes' on relationship 'Movimentacao.matricula': property of that name exists on mapper 'Mapper[Matricula(matricula)]'
2025-05-13 23:57:19,718 INFO: Estoque de Apostilas startup [in C:\Users\nilva\estoque_apostilas\app\__init__.py:59]
2025-05-13 23:57:36,167 INFO: Acessando rota movimentacao [in C:\Users\nilva\estoque_apostilas\app\routes\movimentacoes.py:193]
2025-05-13 23:57:36,173 ERROR: Erro ao carregar movimentações: type object 'Movimentacao' has no attribute 'matricula' [in C:\Users\nilva\estoque_apostilas\app\routes\movimentacoes.py:209]
Traceback (most recent call last):
  File "C:\Users\nilva\estoque_apostilas\app\routes\movimentacoes.py", line 200, in movimentacao
    db.joinedload(Movimentacao.matricula),
                  ^^^^^^^^^^^^^^^^^^^^^^
AttributeError: type object 'Movimentacao' has no attribute 'matricula'. Did you mean: 'matricula_rel'?
2025-05-13 23:59:28,141 INFO: Acessando rota movimentacao [in C:\Users\nilva\estoque_apostilas\app\routes\movimentacoes.py:193]
