2025-05-08 11:09:55,823 INFO: Estoque de Apostilas startup [in C:\Users\nilva\estoque_apostilas\app\__init__.py:66]
2025-05-08 11:13:21,736 INFO: Estoque de Apostilas startup [in C:\Users\nilva\estoque_apostilas\app\__init__.py:66]
2025-05-08 11:36:29,033 INFO: Estoque de Apostilas startup [in C:\Users\nilva\estoque_apostilas\app\__init__.py:66]
2025-05-08 11:54:40,326 INFO: Estoque de Apostilas startup [in C:\Users\nilva\estoque_apostilas\app\__init__.py:66]
2025-05-08 12:01:03,627 INFO: Estoque de Apostilas startup [in C:\Users\nilva\estoque_apostilas\app\__init__.py:66]
2025-05-08 12:03:01,260 INFO: Estoque de Apostilas startup [in C:\Users\nilva\estoque_apostilas\app\__init__.py:66]
2025-05-08 12:03:13,191 ERROR: Exception on /login [POST] [in C:\Users\nilva\AppData\Roaming\Python\Python312\site-packages\flask\app.py:1414]
Traceback (most recent call last):
  File "C:\Users\nilva\AppData\Roaming\Python\Python312\site-packages\flask\app.py", line 2190, in wsgi_app
    response = self.full_dispatch_request()
               ^^^^^^^^^^^^^^^^^^^^^^^^^^^^
  File "C:\Users\nilva\AppData\Roaming\Python\Python312\site-packages\flask\app.py", line 1486, in full_dispatch_request
    rv = self.handle_user_exception(e)
         ^^^^^^^^^^^^^^^^^^^^^^^^^^^^^
  File "C:\Users\nilva\AppData\Roaming\Python\Python312\site-packages\flask\app.py", line 1484, in full_dispatch_request
    rv = self.dispatch_request()
         ^^^^^^^^^^^^^^^^^^^^^^^
  File "C:\Users\nilva\AppData\Roaming\Python\Python312\site-packages\flask\app.py", line 1469, in dispatch_request
    return self.ensure_sync(self.view_functions[rule.endpoint])(**view_args)
           ^^^^^^^^^^^^^^^^^^^^^^^^^^^^^^^^^^^^^^^^^^^^^^^^^^^^^^^^^^^^^^^^^
  File "C:\Users\nilva\estoque_apostilas\app\routes\auth.py", line 18, in login
    current_app.logger.debug("Campos de login vazios.")
    ^^^^^^^^^^^
NameError: name 'current_app' is not defined. Did you mean: 'current_user'?
2025-05-08 12:03:49,463 ERROR: Exception on /login [POST] [in C:\Users\nilva\AppData\Roaming\Python\Python312\site-packages\flask\app.py:1414]
Traceback (most recent call last):
  File "C:\Users\nilva\AppData\Roaming\Python\Python312\site-packages\flask\app.py", line 2190, in wsgi_app
    response = self.full_dispatch_request()
               ^^^^^^^^^^^^^^^^^^^^^^^^^^^^
  File "C:\Users\nilva\AppData\Roaming\Python\Python312\site-packages\flask\app.py", line 1486, in full_dispatch_request
    rv = self.handle_user_exception(e)
         ^^^^^^^^^^^^^^^^^^^^^^^^^^^^^
  File "C:\Users\nilva\AppData\Roaming\Python\Python312\site-packages\flask\app.py", line 1484, in full_dispatch_request
    rv = self.dispatch_request()
         ^^^^^^^^^^^^^^^^^^^^^^^
  File "C:\Users\nilva\AppData\Roaming\Python\Python312\site-packages\flask\app.py", line 1469, in dispatch_request
    return self.ensure_sync(self.view_functions[rule.endpoint])(**view_args)
           ^^^^^^^^^^^^^^^^^^^^^^^^^^^^^^^^^^^^^^^^^^^^^^^^^^^^^^^^^^^^^^^^^
  File "C:\Users\nilva\estoque_apostilas\app\routes\auth.py", line 18, in login
    current_app.logger.debug("Campos de login vazios.")
    ^^^^^^^^^^^
NameError: name 'current_app' is not defined. Did you mean: 'current_user'?
2025-05-08 12:04:17,818 ERROR: Exception on /login [POST] [in C:\Users\nilva\AppData\Roaming\Python\Python312\site-packages\flask\app.py:1414]
Traceback (most recent call last):
  File "C:\Users\nilva\AppData\Roaming\Python\Python312\site-packages\flask\app.py", line 2190, in wsgi_app
    response = self.full_dispatch_request()
               ^^^^^^^^^^^^^^^^^^^^^^^^^^^^
  File "C:\Users\nilva\AppData\Roaming\Python\Python312\site-packages\flask\app.py", line 1486, in full_dispatch_request
    rv = self.handle_user_exception(e)
         ^^^^^^^^^^^^^^^^^^^^^^^^^^^^^
  File "C:\Users\nilva\AppData\Roaming\Python\Python312\site-packages\flask\app.py", line 1484, in full_dispatch_request
    rv = self.dispatch_request()
         ^^^^^^^^^^^^^^^^^^^^^^^
  File "C:\Users\nilva\AppData\Roaming\Python\Python312\site-packages\flask\app.py", line 1469, in dispatch_request
    return self.ensure_sync(self.view_functions[rule.endpoint])(**view_args)
           ^^^^^^^^^^^^^^^^^^^^^^^^^^^^^^^^^^^^^^^^^^^^^^^^^^^^^^^^^^^^^^^^^
  File "C:\Users\nilva\estoque_apostilas\app\routes\auth.py", line 18, in login
    current_app.logger.debug("Campos de login vazios.")
    ^^^^^^^^^^^
NameError: name 'current_app' is not defined. Did you mean: 'current_user'?
2025-05-08 12:05:55,697 INFO: Estoque de Apostilas startup [in C:\Users\nilva\estoque_apostilas\app\__init__.py:66]
2025-05-08 12:24:48,378 INFO: Estoque de Apostilas startup [in C:\Users\nilva\estoque_apostilas\app\__init__.py:66]
2025-05-08 12:40:28,413 INFO: Estoque de Apostilas startup [in C:\Users\nilva\estoque_apostilas\app\__init__.py:59]
2025-05-08 12:53:09,325 INFO: Estoque de Apostilas startup [in C:\Users\nilva\estoque_apostilas\app\__init__.py:59]
